Workbook

Sheet W1 Sheet
H35: SAILPLANE - POWERED SAILPLANE WEIGHING RECORD GFA Form W1 | AP35: {='Aircraft Data'!$A2} -> A blank sheet
AP36: {='Aircraft Data'!$A3} -> ASH 25E
H37: Weighed by | K37: Camden Sailplanes | R37: Place | U37: CAMDEN | Z37: Date | AP37: {='Aircraft Data'!$A4} -> ASH 25m
R38: Data Sheet | AP38: {='Aircraft Data'!$A5} -> ASK 21
H39: Scales used | L39: KELBA | R39: Level Ref | Z39: Datum | AB39: WRLE | AP39: {='Aircraft Data'!$A6} -> ASK21Mi
AP40: {='Aircraft Data'!$A7} -> Astir CS
D41: SAILPLANE - POWERED SAILPLANE DETAILS | AP41: {='Aircraft Data'!$A8} -> ASW19B
D42: Type | I42: Serial Number | P42: C of R | V42: Reg | AB42: Other | AP42: {='Aircraft Data'!$A9} -> Asw20 bl 16mtr
D43: DG1000 utility 18 | P43: No. | Q43: G | V43: VH | AB43: marks | AP43: {='Aircraft Data'!$A10} -> ASW20B
AP44: {='Aircraft Data'!$A11} -> Asw20bl 15mtr
D45: EQUIPMENT LIST -ITEMS FITTED OR NORMALLY CARRIED IN SAILPLANE | AP45: {='Aircraft Data'!$A12} -> Blanik l13
D46: Qty | K46: Qty | S46: Qty | Z46: Qty | AP46: {='Aircraft Data'!$A13} -> Blanik L13 aero
E47: Airspeed indicator (Kts) | L47: Mechanical Variometer | T47: Seat Cushions | AA47: Ltrs Unusuable Fuel | AP47: {='Aircraft Data'!$A14} -> Cirrus
E48: Altimeter (feet) | L48: Electric Variometer | T48: Back Rest | AA48: Tachometer | AP48: {='Aircraft Data'!$A15} -> DG 400 15mtr
E49: Compass | L49: Air Data Computer | T49: Head Rest | AA49: Engine Controller/monitor | AP49: {='Aircraft Data'!$A16} -> DG 400 17mtr
E50: Radio | L50: GPS | T50: Tie Down Kit | AA50: CO Detector | AP50: {='Aircraft Data'!$A17} -> DG1000 aero 18
G51: Kg | H51: Battery | L51: Data Logger | T51: Tail Parachute | AA51: Rear View Mirrors | AP51: {='Aircraft Data'!$A18} -> DG1000 utility 18
E52: Oxygen equipment | L52: Other Instruments | T52: Water Ballast Bags | AA52: Other Engine equipment | AP52: {='Aircraft Data'!$A19} -> DG1000 utility 20
P53: MEASUREMENTS AND CALCULATIONS | AP53: {='Aircraft Data'!$A20} -> DG303
AP54: {='Aircraft Data'!$A21} -> DG500M-XQA
P55: All dimensions are taken as positive | AP55: {='Aircraft Data'!$A22} -> Duo Discus M
AP56: {='Aircraft Data'!$A23} -> G103 Acro 600kg
P57: LEFT WING | Y57: RIGHT WING | AP57: {='Aircraft Data'!$A24} -> Grob 109A
AP58: {='Aircraft Data'!$A25} -> Grob103 twin500kg
P59: Winglet | X59: kg | Y59: Winglet | AG59: kg | AP59: {='Aircraft Data'!$A26} -> Hornet
P60: Outer panel | X60: kg | Y60: Outer panel | AG60: kg | AP60: {='Aircraft Data'!$A27} -> IS28 B2
P61: Inner panel | T61: 93.5 | X61: kg | Y61: Inner panel | AC61: 93 | AG61: kg | AP61: {='Aircraft Data'!$A28} -> IS28 B2 Aero
P62: Total left wing | T62: {=T59+T60+T61} -> 93.5 | X62: kg | Y62: Total Right wing | AC62: {=SUM(AC59+AC60+AC61)} -> 93 | AG62: kg | AP62: {='Aircraft Data'!$A29} -> Jantar Junior
AP63: {='Aircraft Data'!$A30} -> Jantar std2
P64: Main wheels or Nose wheel see Model | Y64: Add Left Wing | AP64: {='Aircraft Data'!$A31} -> Jantar Std3
P65: G1 Left + | S65: G1 Right = | V65: G1 | AC65: {=$T$62} -> 93.5 | AG65: kg | AP65: {='Aircraft Data'!$A32} -> LS1f
P66: 364.5 | V66: {=IF(P66+S66=0,AI75,P66+S66)} -> 364.5 | Y66: Add main pin/s | AP66: {='Aircraft Data'!$A33} -> LS4
X67: kg | Y67: (See manual) | AG67: kg | AP67: {='Aircraft Data'!$A34} -> LS4A
P68: Main wheels or Tail wheel see Model | Y68: ************* | AP68: {='Aircraft Data'!$A35} -> LS6
P69: G2 Left + | S69: G2 Right = | V69: G2 | Y69: Total Wings | AP69: {='Aircraft Data'!$A36} -> LS8-18
P70: 47 | V70: {=IF((P70+S70)=0,AI75,(P70+S70))} -> 47 | Y70: Structure weight | AC70: {=SUM($T$62+$AC$62+$AC$67)} -> 186.5 | AG70: kg | AI70: Quick calculator | AP70: {='Aircraft Data'!$A37} -> Mossy
X71: kg | AI71: Total weight of aircraft at main wheel & tail wheel | AP71: {='Aircraft Data'!$A38} -> Nimbus 3 DM
P72: Total Empty Weight | Y72: a + b | AJ72: Kg direct from scales | AP72: {='Aircraft Data'!$A39} -> Nimbus 3T 22m
T73: G | U73: {=SUM($V$70+$V$66)} -> 411.5 | X73: kg | Y73: Type 1 only | AC73: {=IF(Z83=1,($AC$76+$AC$79),"n/a")} -> 5303 | AG73: mm | AP73: {='Aircraft Data'!$A40} -> Nimbus 3T 24m | AS73: 1
P74: Less Total - Wings | AI74: {=IF((P70+S70)=0,(P66+S66),(P70+S70))} -> 47 | AJ74: Kg this can be G1 or G2 check model | AP74: {='Aircraft Data'!$A41} -> Nimbus 3T 25m | AS74: 1a
...

Sheet Calculations
B2: WEIGHT and BALANCE CALCULATIONS
B3: Data from the Weight and Balance sheet (W1) & Aircraft data base.
B4: {='W1 Sheet'!D43} -> DG1000 utility 18 | E4: {='W1 Sheet'!W43} -> 0 | I4: Model | K4: {='W1 Sheet'!Z83} -> 1
C5: This data is automatic from the W1 sheet | I5: Calculated data
C6: Moment "a" | E6: {='W1 Sheet'!$AC$76} -> 114 | F6: mm | I6: Empty c of g "X" | K6: {='W1 Sheet'!$AC$83} | L6: mm Eq1
C7: Moment "b" | E7: {='W1 Sheet'!$AC$79} -> 5189 | F7: mm
I8: X safe c/g "Xa Safe" | K8: {=SUM($E$19-(0.05*($E$19-$E$18)))} -> 427.5 | L8: mm Eq4
C9: Empty weight "G" | E9: {='W1 Sheet'!$U$73} -> 411.5 | F9: Kg
C10: Rear weight "G2" | E10: {='W1 Sheet'!$V$70} -> 47 | F10: Kg | I10: Pilot 1 min weight | K10: {=IF(ISERROR(('W1 Sheet'!$U$73*('W1 Sheet'!$AC$83-$K$8)/($K$8-($E$22)))),"No data",ROUNDUP(('W1 Sheet'!$U$73*('W1 Sheet'!$AC$83-$K$8)/($K$8-($E$22))),0))} -> No data | L10: Kg Eq5
C11: Front weight "G1" | E11: {='W1 Sheet'!$V$66} -> 364.5 | F11: Kg
C12: Right wing "rw" | E12: {='W1 Sheet'!$AC$62} -> 93 | F12: Kg | I12: Max FWD C of G | K12: {=IF(ISERROR(('W1 Sheet'!$AC$83-$E$18)/($E$18-($E$22))*'W1 Sheet'!$U$73),"No data",SUM('W1 Sheet'!$AC$83-$E$18)/($E$18-($E$22))*'W1 Sheet'!$U$73)} -> No data | L12: Kg Eq9
C13: Left wing "lw" | E13: {='W1 Sheet'!$T$62} -> 93.5 | F13: Kg
C14: Fuse + tailplane "G3" | E14: {='W1 Sheet'!$U$78} -> 225 | F14: Kg | I14: Max seat limit | K14: 110 | L14: Kg GFA
C16: This data is entered automatically, please check issue date. | I16: Max weight DRY | K16: {=IF($E$21=0,0,$E$21-'W1 Sheet'!$U$73)} -> 244.5 | L16: Kg Eq7
C18: c of g fwd "xf" | E18: 190 | F18: mm | I18: Max weight WET | K18: {=IF(OR($E$20=0,$E$26=0),"N/A",$E$20-'W1 Sheet'!$U$73)} -> 338.5 | L18: Kg Eq6
C19: c of g aft "xa" | E19: 440 | F19: mm | N19: Weight of non-lift parts
C20: Max weight wet "G6" | E20: 750 | F20: Kg | I20: Max NON lift parts | K20: {=IF($E$24=0,"N/A",$E$24-'W1 Sheet'!$U$78)} -> 244 | L20: Kg Eq8 | O20: No entry req
C21: Max weight dry "G5" | E21: 656 | F21: Kg | N21: NO data was found in the database for this
C22: Pilot moment "Xp1" | E22: -1335 | F22: mm | I22: Max seat load(gfa) | K22: 110 | L22: Kg | N22: aircraft please enter manually
C23: Rear pilot moment Xp2 | E23: -272 | F23: mm | I23: {=IF($E$23<>0,"If two pilots see max fuselage load below","")} -> If two pilots see max fuselage load below | N23: Enter data here >>>> | P23: 0 | Q23: Kg
C24: Max non fly "G4" | E24: 469 | F24: Kg | I24: Max avail. load WET | K24: {=IF($E$20=0,"N/A",IF($E$23=0,"N/A",$E$20-'W1 Sheet'!$U$73))} -> 338.5 | L24: Kg
C25: Ballast moment "Bm" | E25: -1960 | F25: mm | I25: Two seat only | N25: The information should be available in the
C26: Max water allowed | E26: 160 | F26: Ltr | I26: Max fuse load | K26: {=IF($E$21=0,"N/A",IF(OR('W1 Sheet'!$U$78=0,$E$23=0),"N/A",MIN(($E$21-'W1 Sheet'!$U$73),($E$24-'W1 Sheet'!$U$78))))} -> 244 | L26: Kg | N26: aircraft manual
D27: Issue Date | E27: 0 | I27: Two seat only
I28: Min P2 for Min rear | K28: {=IF($E$23=0,0,((('W1 Sheet'!$U$73*'W1 Sheet'!$AC$83)+($E$22*20)-($K$8*'W1 Sheet'!$U$73)-($K$8*20))/($K$8-$E$23)))} | L28: Kg Eq10
C29: NOTE Xp1 and Bm are negative | I29: C/G @ P1 =20Kg
C30: if forward of datum | I30: Max P2 for Max rear | K30: {=IF($E$23=0,0,IF($E$26=0,($E$21-'W1 Sheet'!$U$73-20),($E$20-'W1 Sheet'!$U$73-20)))} -> 318.5 | L30: Kg Eq11
C31: Xp2 is positive if behind the datum. | I31: C/G @ P1=20Kg
B32: Max water @ Max pilot weight of | I32: Max NON lift parts | K32: {=IF(OR($E$23=0,$E$24=0),"N/A",($E$24-'W1 Sheet'!$U$78-20))} -> 224 | L32: Kg Eq12
E33: {=IF($E$26=0,"NO water",$K$22)} -> 110 | F33: {=IF($E$26=0,0,IF(SUM($E$20-'W1 Sheet'!$U$73-$K$22)>$E$26,$E$26,$E$20-'W1 Sheet'!$U$73-$K$22))} -> 160 | I33: P1 =20Kg
B34: using Eq14 | E34: Kg | F34: Ltrs | I34: Max P2 for Max fwd | K34: {=IF($E$23=0,0,SUM(((('W1 Sheet'!$U$73*'W1 Sheet'!$AC$83)+($E$22*20)-($E$18*'W1 Sheet'!$U$73)-($E$18*20))/($E$18-$E$23))))} | L34: Kg Eq13
I35: C/G @ P1 =20Kg
I36: See placards for full P1 - P2 range.

Sheet Load limits
B3: {=IF('W1 Sheet'!D43="A blank sheet","",LEFT('W1 Sheet'!D43,11))} -> DG1000 util | D3: {='W1 Sheet'!W43} -> 0 | E3: LOADING PLAN | J3: {=IF('W1 Sheet'!D43="A blank sheet","",LEFT('W1 Sheet'!D43,11))} -> DG1000 util | M3: {='W1 Sheet'!W43} -> 0 | N3: LOADING PLAN
B4: NO BALLAST + FUEL | L4: {=$G$28} -> 0 | M4: Kg BALLAST + FUEL
B5: This chart DOES NOT apply when the spin kit is fitted. | K5: This chart DOES NOT apply when the spin kit is fitted.
C6: No Ballast NO fuel | E6: NO Ballast half fuel | G6: NO ballast full fuel | L6: Ballast NO fuel | N6: Ballast / half fuel | P6: Ballast / full fuel
E7: {=M28/2} -> 10 | F7: Litres | G7: {=M28} -> 20 | H7: Litres | L7: {=$G$28} -> 0 | M7: Kg | N7: {=$G$28} -> 0 | O7: {=M28/2} -> 10 | P7: {=$G$28} -> 0 | Q7: {=M28} -> 20
B8: min P1 | C8: min P2 | D8: Max P2 | E8: min P2 | F8: Maxp2 | G8: min P2 | H8: Maxp2 | K8: min P1 | L8: min P2 | M8: Maxp2 | N8: min P2 | O8: Maxp2 | P8: min P2 | Q8: Maxp2
B9: 25 | C9: {='Placards'!T34} -> 0 | D9: {='Placards'!U34} -> 0 | E9: {='Placards'!BC34} -> 0 | F9: {='Placards'!BD34} -> 0 | G9: {='Placards'!BL34} -> 0 | H9: {='Placards'!BM34} -> 0 | K9: 25 | L9: {='Placards'!AB34} -> 0 | M9: {='Placards'!AC34} -> 0 | N9: {='Placards'!AK34} -> 0 | O9: {='Placards'!AL34} -> 0 | P9: {='Placards'!AT34} -> 0 | Q9: {='Placards'!AU34} -> 0
B10: 30 | C10: {='Placards'!T35} -> 0 | D10: {='Placards'!U35} -> 0 | E10: {='Placards'!BC35} -> 0 | F10: {='Placards'!BD35} -> 0 | G10: {='Placards'!BL35} -> 0 | H10: {='Placards'!BM35} -> 0 | K10: 30 | L10: {='Placards'!AB35} -> 0 | M10: {='Placards'!AC35} -> 0 | N10: {='Placards'!AK35} -> 0 | O10: {='Placards'!AL35} -> 0 | P10: {='Placards'!AT35} -> 0 | Q10: {='Placards'!AU35} -> 0
B11: 35 | C11: {='Placards'!T36} -> 0 | D11: {='Placards'!U36} -> 0 | E11: {='Placards'!BC36} -> 0 | F11: {='Placards'!BD36} -> 0 | G11: {='Placards'!BL36} -> 0 | H11: {='Placards'!BM36} -> 0 | K11: 35 | L11: {='Placards'!AB36} -> 0 | M11: {='Placards'!AC36} -> 0 | N11: {='Placards'!AK36} -> 0 | O11: {='Placards'!AL36} -> 0 | P11: {='Placards'!AT36} -> 0 | Q11: {='Placards'!AU36} -> 0
B12: 40 | C12: {='Placards'!T37} -> 0 | D12: {='Placards'!U37} -> 0 | E12: {='Placards'!BC37} -> 0 | F12: {='Placards'!BD37} -> 0 | G12: {='Placards'!BL37} -> 0 | H12: {='Placards'!BM37} -> 0 | K12: 40 | L12: {='Placards'!AB37} -> 0 | M12: {='Placards'!AC37} -> 0 | N12: {='Placards'!AK37} -> 0 | O12: {='Placards'!AL37} -> 0 | P12: {='Placards'!AT37} -> 0 | Q12: {='Placards'!AU37} -> 0
B13: 45 | C13: {='Placards'!T38} -> 0 | D13: {='Placards'!U38} -> 0 | E13: {='Placards'!BC38} -> 0 | F13: {='Placards'!BD38} -> 0 | G13: {='Placards'!BL38} -> 0 | H13: {='Placards'!BM38} -> 0 | K13: 45 | L13: {='Placards'!AB38} -> 0 | M13: {='Placards'!AC38} -> 0 | N13: {='Placards'!AK38} -> 0 | O13: {='Placards'!AL38} -> 0 | P13: {='Placards'!AT38} -> 0 | Q13: {='Placards'!AU38} -> 0
B14: 50 | C14: {='Placards'!T39} -> 0 | D14: {='Placards'!U39} -> 0 | E14: {='Placards'!BC39} -> 0 | F14: {='Placards'!BD39} -> 0 | G14: {='Placards'!BL39} -> 0 | H14: {='Placards'!BM39} -> 0 | K14: 50 | L14: {='Placards'!AB39} -> 0 | M14: {='Placards'!AC39} -> 0 | N14: {='Placards'!AK39} -> 0 | O14: {='Placards'!AL39} -> 0 | P14: {='Placards'!AT39} -> 0 | Q14: {='Placards'!AU39} -> 0
B15: 55 | C15: {='Placards'!T40} -> 0 | D15: {='Placards'!U40} -> 0 | E15: {='Placards'!BC40} -> 0 | F15: {='Placards'!BD40} -> 0 | G15: {='Placards'!BL40} -> 0 | H15: {='Placards'!BM40} -> 0 | K15: 55 | L15: {='Placards'!AB40} -> 0 | M15: {='Placards'!AC40} -> 0 | N15: {='Placards'!AK40} -> 0 | O15: {='Placards'!AL40} -> 0 | P15: {='Placards'!AT40} -> 0 | Q15: {='Placards'!AU40} -> 0
B16: 60 | C16: {='Placards'!T41} -> 0 | D16: {='Placards'!U41} -> 0 | E16: {='Placards'!BC41} -> 0 | F16: {='Placards'!BD41} -> 0 | G16: {='Placards'!BL41} -> 0 | H16: {='Placards'!BM41} -> 0 | K16: 60 | L16: {='Placards'!AB41} -> 0 | M16: {='Placards'!AC41} -> 0 | N16: {='Placards'!AK41} -> 0 | O16: {='Placards'!AL41} -> 0 | P16: {='Placards'!AT41} -> 0 | Q16: {='Placards'!AU41} -> 0
B17: 65 | C17: {='Placards'!T42} -> 0 | D17: {='Placards'!U42} -> 0 | E17: {='Placards'!BC42} -> 0 | F17: {='Placards'!BD42} -> 0 | G17: {='Placards'!BL42} -> 0 | H17: {='Placards'!BM42} -> 0 | K17: 65 | L17: {='Placards'!AB42} -> 0 | M17: {='Placards'!AC42} -> 0 | N17: {='Placards'!AK42} -> 0 | O17: {='Placards'!AL42} -> 0 | P17: {='Placards'!AT42} -> 0 | Q17: {='Placards'!AU42} -> 0
B18: 70 | C18: {='Placards'!T43} -> 0 | D18: {='Placards'!U43} -> 0 | E18: {='Placards'!BC43} -> 0 | F18: {='Placards'!BD43} -> 0 | G18: {='Placards'!BL43} -> 0 | H18: {='Placards'!BM43} -> 0 | K18: 70 | L18: {='Placards'!AB43} -> 0 | M18: {='Placards'!AC43} -> 0 | N18: {='Placards'!AK43} -> 0 | O18: {='Placards'!AL43} -> 0 | P18: {='Placards'!AT43} -> 0 | Q18: {='Placards'!AU43} -> 0
B19: 75 | C19: {='Placards'!T44} -> 0 | D19: {='Placards'!U44} -> 0 | E19: {='Placards'!BC44} -> 0 | F19: {='Placards'!BD44} -> 0 | G19: {='Placards'!BL44} -> 0 | H19: {='Placards'!BM44} -> 0 | K19: 75 | L19: {='Placards'!AB44} -> 0 | M19: {='Placards'!AC44} -> 0 | N19: {='Placards'!AK44} -> 0 | O19: {='Placards'!AL44} -> 0 | P19: {='Placards'!AT44} -> 0 | Q19: {='Placards'!AU44} -> 0
B20: 80 | C20: {='Placards'!T45} -> 0 | D20: {='Placards'!U45} -> 0 | E20: {='Placards'!BC45} -> 0 | F20: {='Placards'!BD45} -> 0 | G20: {='Placards'!BL45} -> 0 | H20: {='Placards'!BM45} -> 0 | K20: 80 | L20: {='Placards'!AB45} -> 0 | M20: {='Placards'!AC45} -> 0 | N20: {='Placards'!AK45} -> 0 | O20: {='Placards'!AL45} -> 0 | P20: {='Placards'!AT45} -> 0 | Q20: {='Placards'!AU45} -> 0
... B25: 105 | C25: {='Placards'!T50} -> 0 | D25: {='Placards'!U50} -> 0 | E25: {='Placards'!BC50} -> 0 | F25: {='Placards'!BD50} -> 0 | G25: {='Placards'!BL50} -> 0 | H25: {='Placards'!BM50} -> 0 | K25: 105 | L25: {='Placards'!AB50} -> 0 | M25: {='Placards'!AC50} -> 0 | N25: {='Placards'!AK50} -> 0 | O25: {='Placards'!AL50} -> 0 | P25: {='Placards'!AT50} -> 0 | Q25: {='Placards'!AU50} -> 0
B26: 110 | C26: {='Placards'!T51} -> 0 | D26: {='Placards'!U51} -> 0 | E26: {='Placards'!BC51} -> 0 | F26: {='Placards'!BD51} -> 0 | G26: {='Placards'!BC51} -> 0 | H26: {='Placards'!BM51} -> 0 | K26: 110 | L26: {='Placards'!AB51} -> 0 | M26: {='Placards'!AC51} -> 0 | N26: {='Placards'!AK51} -> 0 | O26: {='Placards'!AL51} -> 0 | P26: {='Placards'!AT51} -> 0 | Q26: {='Placards'!AU51} -> 0
B27: This chart in NO way relieves the pilot in command his duty of | K27: care to ensure all weight and balance factors are considered.
D28: This plan is set for | G28: 0 | H28: Kg of ballast and | M28: 20 | N28: litres of fuel
D29: To change the amount of ballast or fuel enter the new amount in the above cells then press enter.
G30: {=IF(OR($G$28="",$G$28=0),0,$G$28)} -> 0 | M30: {=IF(OR($M$28="",$M$28=0),0,$M$28)} -> 20
D31: 1 litre of petrol weighs 0.75 kilograms therefore | K31: {=M28} -> 20 | L31: litres weighs | N31: {=$M$34} -> 15 | O31: kilograms
M34: {=M28*0.75} -> 15
M35: {=M28*0.75/2} -> 7.5

Sheet W2 Sheet
C2: SAILPLANE WEIGHT & BALANCE SUMMARY | D2: SAILPLANE WEIGHT AND BALANCE SUMMARY
E3: GFA FORM W2
C5: TYPE | D5: {='W1 Sheet'!D43:H43} | F5: Ser No. | G5: {='W1 Sheet'!I43} -> 0 | J5: Reg VH- | K5: {='W1 Sheet'!W43} -> 0
C6: DATUM | D6: {='W1 Sheet'!AB39} -> WRLE
C7: EMPTY WEIGHT TAKEN FROM W1 | F7: {='W1 Sheet'!$U$73} -> 411.5 | G7: Kg
C8: CENTRE OF GRAVITY LIMITS | F8: FORWARD | G8: {='Calculations'!$E$18} -> 190 | H8: MM | I8: AFT | J8: {='Calculations'!$K$8} -> 427.5 | K8: MM
C9: MAXIMUM WEIGHT OF NON LIFTING PARTS | G9: {='Calculations'!$E$24} -> 469 | H9: Kg
F11: Weight | G11: Weight | H11: Item | I11: Total | J11: Total | K11: Total | L11: Percent of
C12: Item No. | D12: Item | E12: Arm | F12: removed | G12: added | H12: moment | I12: weight | J12: arm | K12: moment | L12: usable
F13: (-) | G13: (+) | I13: Kg | J13: mm | L13: flight range
C14: 0 | D14: Empty sailplane | E14: ********* | F14: ********* | G14: ************ | H14: ********* | I14: {='W1 Sheet'!$U$73} -> 411.5 | J14: {='W1 Sheet'!$AC$83} | K14: {=IF(I14=0,0,J14*I14)} | L14: ************
C15: 1
C16: 2 | D16: P1 pilot weight | E16: {='Calculations'!$E$22} -> -1335 | G16: 50 | H16: {=IF(E16=0,0,G16*E16)} -> -66750 | I16: {=$I$14+G16} -> 461.5 | J16: {=IF(ISERROR(K16/I16),0,K16/I16)} -> 0 | K16: {=$K$14+(H16)} | L16: {=IF(ISERROR(100/(('Calculations'!$E$19-'Calculations'!$E$18)/(J16-'Calculations'!$E$18))),"",100/(('Calculations'!$E$19-'Calculations'!$E$18)/(J16-'Calculations'!$E$18)))} -> -76 | N16: Cells in MAUVE can be filled
C17: 3 | N17: by the user to see the effect
C18: 4 | D18: P2 pilot weight | E18: {='Calculations'!$E$23} -> -272 | G18: 110 | H18: {=IF(E18=0,0,G18*E18)} -> -29920 | I18: {=IF(G18=0,0,$I$14+G18+G16)} -> 571.5 | J18: {=IF(ISERROR(K18/I18),0,K18/I18)} -> 0 | K18: {=IF(H18=0,0,$K$14+H18+H16)} | L18: {=IF(J18=0,"",(100/(('Calculations'!$E$19-'Calculations'!$E$18)/(J18-'Calculations'!$E$18))))} | N18: on the CofG position
C19: 5 | M19: If columns Total Weight or Total Arm
C20: 6 | D20: Ballast in tail | E20: 5400 | H20: {=IF(E20=0,0,G20*E20)} -> 0 | I20: {=IF(G20=0,0,$I$14+G20+G18+G16)} -> 0 | J20: {=IF(ISERROR(K20/I20),0,K20/I20)} -> 0 | K20: {=IF(H20=0,0,$K$14+H20+H18+H16)} -> 0 | L20: {=IF(J20=0,"",(100/(('Calculations'!$E$19-'Calculations'!$E$18)/(J20-'Calculations'!$E$18))))} | M20: are not green then you are outside
C21: 7 | J21: {=IF(ISERROR(K21/I21),0,K21/I21)} -> 0 | M21: the CofG limits or MAXIMUM weight.
C22: 8 | D22: Cockpit ballast | E22: -1960 | H22: {=IF(E22=0,0,G22*E22)} -> 0 | I22: {=IF(G22=0,0,$I$14+G22+G20+G18+G16)} -> 0 | J22: {=IF(ISERROR(K22/I22),0,K22/I22)} -> 0 | K22: {=IF(H22=0,0,$K$14+H20+H18+H16+H22)} -> 0 | L22: {=IF(J22=0,"",(100/(('Calculations'!$E$19-'Calculations'!$E$18)/(J22-'Calculations'!$E$18))))}
C23: 9
C24: 10 | D24: Fuel | E24: 0 | H24: {=IF(E24=0,0,G24*E24)} -> 0 | I24: {=IF(G24=0,0,$I$14+G24+G22+G20+G18+G16)} -> 0 | J24: {=IF(ISERROR(K24/I24),0,K24/I24)} -> 0 | K24: {=IF(H24=0,0,$K$14+H22+H20+H18+H24+H16)} -> 0 | L24: {=IF(J24=0,"",(100/(('Calculations'!$E$19-'Calculations'!$E$18)/(J24-'Calculations'!$E$18))))}
C25: 11
C26: 12 | H26: {=IF(E26=0,0,(-F26+G26)*E26)} -> 0 | I26: {=IF(G26=0,0,$I$14+G26+G24+G22+G20+G18+G16-F26)} -> 0 | J26: {=IF(ISERROR(K26/I26),0,K26/I26)} -> 0 | K26: {=IF(H26=0,0,$K$14+H24+H22+H20+H26+H18+H16)} -> 0 | L26: {=IF(J26=0,"",(100/(('Calculations'!$E$19-'Calculations'!$E$18)/(J26-'Calculations'!$E$18))))}
C27: 13 | H27: {=IF(E27=0,0,(-F27+G27)*E27)} -> 0
C28: 14 | H28: {=IF(E28=0,0,(-F28+G28)*E28)} -> 0 | I28: {=IF(G28=0,0,$I$14+G28+G26+G24+G22+G20+G18+G16-F28-F26)} -> 0 | J28: {=IF(ISERROR(K28/I28),0,K28/I28)} -> 0 | K28: {=IF(H28=0,0,$K$14+H26+H24+H22+H28+H20+H18+H16)} -> 0 | L28: {=IF(J28=0,"",(100/(('Calculations'!$E$19-'Calculations'!$E$18)/(J28-'Calculations'!$E$18))))}
C29: 15 | H29: {=IF(E29=0,0,(-F29+G29)*E29)} -> 0
C30: 16 | H30: {=IF(E30=0,0,(-F30+G30)*E30)} -> 0 | I30: {=IF(G30=0,0,$I$14+G30+G28+G26+G24+G22+G20+G18+G16-F30-F28-F26)} -> 0 | J30: {=IF(ISERROR(K30/I30),0,K30/I30)} -> 0 | K30: {=IF(H30=0,0,$K$14+H28+H26+H24+H30+H22+H20+H18+H16)} -> 0 | L30: {=IF(J30=0,"",(100/(('Calculations'!$E$19-'Calculations'!$E$18)/(J30-'Calculations'!$E$18))))}
C31: 17
D33: PLACARDING INFORMATION
D34: MAXIMUM TAKEOFF WEIGHT | G34: {='Calculations'!$E$20} -> 750 | H34: Kg wet
D35: MAXIMUM TAKEOFF WEIGHT | G35: {='Calculations'!$E$21} -> 656 | H35: Kg dry
D36: EMPTY WEIGHT | G36: {='W1 Sheet'!$U$73} -> 411.5 | H36: Kg
D37: MINIMUM PILOT WEIGHT | G37: {='Calculations'!$K$10} -> No data | H37: Kg
D38: MAXIMUM PILOT WEIGHT | G38: {='Calculations'!$K$22} -> 110 | H38: Kg
D39: MAXIMUM WEIGHT NON LIFT PARTS | G39: 244 | H39: Kg
L40: c.wylie 2011
D47: Authorised person | F47: GFA 1109G | H47: Date

Sheet Placards
B2: WEIGHT and BALANCE CALCULATIONS
E3: Model No. | H3: {='W1 Sheet'!Z83} -> 1
D5: {='W1 Sheet'!D43} -> DG1000 utility 18 | H5: VH- | I5: {='W1 Sheet'!W43} -> 0
H6: Required ballast blocks for
D7: Water Ballast | H7: Minimum pilot weight
B8: Payload | D8: Payload | E8: Max water ltrs | H8: Pilot | I8: Ballast | J8: Block | K8: Total
B9: increments | D9: Kg | H9: weight | I9: block | J9: weight | K9: ballast
B10: please | D10: {='Calculations'!$K$10} -> No data | E10: {=IF(OR('Calculations'!$E$26=0,D10>'Calculations'!$K$22),"",IF(SUM('Calculations'!$E$20-'W1 Sheet'!$U$73-D10)>'Calculations'!$E$26,'Calculations'!$E$26,SUM('Calculations'!$E$20-'W1 Sheet'!$U$73-D10)))} | H10: Kg | I10: no | J10: Kg | K10: weight Kg
B11: enter req | D11: {=IF(OR((D10=""),(D10='Calculations'!$K$22)),"",IF((D10)>='Calculations'!$K$22,"",IF((D10+$B$16)>='Calculations'!$K$22,'Calculations'!$K$22,(D10+$B$16))))} | E11: {=IF(OR('Calculations'!$E$26=0,D11>'Calculations'!$K$22),"",IF(SUM('Calculations'!$E$20-'W1 Sheet'!$U$73-D11)>'Calculations'!$E$26,'Calculations'!$E$26,SUM('Calculations'!$E$20-'W1 Sheet'!$U$73-D11)))} | H11: {=IF('Calculations'!$K$10="No data","No data",ROUNDUP(SUM(('W1 Sheet'!$U$73*('W1 Sheet'!$AC$83-'Calculations'!$K$8))+(K11*('Calculations'!$E$25-'Calculations'!$K$8)))/('Calculations'!$K$8-('Calculations'!$E$22)),0))} -> No data | I11: 0 | J11: 0 | K11: 0
B12: increment | D12: {=IF(OR((D11=""),(D11='Calculations'!$K$22)),"",IF((D11)>='Calculations'!$K$22,"",IF((D11+$B$16)>='Calculations'!$K$22,'Calculations'!$K$22,(D11+$B$16))))} | E12: {=IF(OR('Calculations'!$E$26=0,D12>'Calculations'!$K$22),"",IF(SUM('Calculations'!$E$20-'W1 Sheet'!$U$73-D12)>'Calculations'!$E$26,'Calculations'!$E$26,SUM('Calculations'!$E$20-'W1 Sheet'!$U$73-D12)))} | H12: {=IF('Calculations'!$K$10="No data","",ROUNDUP(SUM(('W1 Sheet'!$U$73*('W1 Sheet'!$AC$83-'Calculations'!$K$8))+(K12*('Calculations'!$E$25-'Calculations'!$K$8)))/('Calculations'!$K$8-('Calculations'!$E$22)),0))} | I12: 1 | J12: 4 | K12: {=I12*J12} -> 4
B13: the default | D13: {=IF(OR((D12=""),(D12='Calculations'!$K$22)),"",IF((D12)>='Calculations'!$K$22,"",IF((D12+$B$16)>='Calculations'!$K$22,'Calculations'!$K$22,(D12+$B$16))))} | E13: {=IF(OR('Calculations'!$E$26=0,D13>'Calculations'!$K$22),"",IF(SUM('Calculations'!$E$20-'W1 Sheet'!$U$73-D13)>'Calculations'!$E$26,'Calculations'!$E$26,SUM('Calculations'!$E$20-'W1 Sheet'!$U$73-D13)))} | H13: {=IF('Calculations'!$K$10="No data","",ROUNDUP(SUM(('W1 Sheet'!$U$73*('W1 Sheet'!$AC$83-'Calculations'!$K$8))+(K13*('Calculations'!$E$25-'Calculations'!$K$8)))/('Calculations'!$K$8-('Calculations'!$E$22)),0))} | I13: 2 | J13: 4 | K13: {=I13*J13} -> 8
B14: is 5 kg | D14: {=IF(OR((D13=""),(D13='Calculations'!$K$22)),"",IF((D13)>='Calculations'!$K$22,"",IF((D13+$B$16)>='Calculations'!$K$22,'Calculations'!$K$22,(D13+$B$16))))} | E14: {=IF(OR('Calculations'!$E$26=0,D14>'Calculations'!$K$22),"",IF(SUM('Calculations'!$E$20-'W1 Sheet'!$U$73-D14)>'Calculations'!$E$26,'Calculations'!$E$26,SUM('Calculations'!$E$20-'W1 Sheet'!$U$73-D14)))} | H14: {=IF('Calculations'!$K$10="No data","",ROUNDUP(SUM(('W1 Sheet'!$U$73*('W1 Sheet'!$AC$83-'Calculations'!$K$8))+(K14*('Calculations'!$E$25-'Calculations'!$K$8)))/('Calculations'!$K$8-('Calculations'!$E$22)),0))} | I14: 3 | J14: 4 | K14: {=I14*J14} -> 12
B15: 1 | D15: {=IF(OR((D14=""),(D14='Calculations'!$K$22)),"",IF((D14)>='Calculations'!$K$22,"",IF((D14+$B$16)>='Calculations'!$K$22,'Calculations'!$K$22,(D14+$B$16))))} | E15: {=IF(OR('Calculations'!$E$26=0,D15>'Calculations'!$K$22),"",IF(SUM('Calculations'!$E$20-'W1 Sheet'!$U$73-D15)>'Calculations'!$E$26,'Calculations'!$E$26,SUM('Calculations'!$E$20-'W1 Sheet'!$U$73-D15)))} | H15: {=IF('Calculations'!$K$10="No data","",ROUNDUP(SUM(('W1 Sheet'!$U$73*('W1 Sheet'!$AC$83-'Calculations'!$K$8))+(K15*('Calculations'!$E$25-'Calculations'!$K$8)))/('Calculations'!$K$8-('Calculations'!$E$22)),0))} | I15: 4 | J15: 4 | K15: {=I15*J15} -> 16
B16: {=IF(OR($B$15="",$B$15=0),5,$B$15)} -> 1 | D16: {=IF(OR((D15=""),(D15='Calculations'!$K$22)),"",IF((D15)>='Calculations'!$K$22,"",IF((D15+$B$16)>='Calculations'!$K$22,'Calculations'!$K$22,(D15+$B$16))))} | E16: {=IF(OR('Calculations'!$E$26=0,D16>'Calculations'!$K$22),"",IF(SUM('Calculations'!$E$20-'W1 Sheet'!$U$73-D16)>'Calculations'!$E$26,'Calculations'!$E$26,SUM('Calculations'!$E$20-'W1 Sheet'!$U$73-D16)))} | H16: {=IF('Calculations'!$K$10="No data","",ROUNDUP(SUM(('W1 Sheet'!$U$73*('W1 Sheet'!$AC$83-'Calculations'!$K$8))+(K16*('Calculations'!$E$25-'Calculations'!$K$8)))/('Calculations'!$K$8-('Calculations'!$E$22)),0))}
B17: Then press | D17: {=IF(OR((D16=""),(D16='Calculations'!$K$22)),"",IF((D16)>='Calculations'!$K$22,"",IF((D16+$B$16)>='Calculations'!$K$22,'Calculations'!$K$22,(D16+$B$16))))} | E17: {=IF(OR('Calculations'!$E$26=0,D17>'Calculations'!$K$22),"",IF(SUM('Calculations'!$E$20-'W1 Sheet'!$U$73-D17)>'Calculations'!$E$26,'Calculations'!$E$26,SUM('Calculations'!$E$20-'W1 Sheet'!$U$73-D17)))} | H17: {=IF('Calculations'!$K$10="No data","",ROUNDUP(SUM(('W1 Sheet'!$U$73*('W1 Sheet'!$AC$83-'Calculations'!$K$8))+(K17*('Calculations'!$E$25-'Calculations'!$K$8)))/('Calculations'!$K$8-('Calculations'!$E$22)),0))}
B18: enter | D18: {=IF(OR((D17=""),(D17='Calculations'!$K$22)),"",IF((D17)>='Calculations'!$K$22,"",IF((D17+$B$16)>='Calculations'!$K$22,'Calculations'!$K$22,(D17+$B$16))))} | E18: {=IF(OR('Calculations'!$E$26=0,D18>'Calculations'!$K$22),"",IF(SUM('Calculations'!$E$20-'W1 Sheet'!$U$73-D18)>'Calculations'!$E$26,'Calculations'!$E$26,SUM('Calculations'!$E$20-'W1 Sheet'!$U$73-D18)))} | H18: {=IF('Calculations'!$K$10="No data","",ROUNDUP(SUM(('W1 Sheet'!$U$73*('W1 Sheet'!$AC$83-'Calculations'!$K$8))+(K18*('Calculations'!$E$25-'Calculations'!$K$8)))/('Calculations'!$K$8-('Calculations'!$E$22)),0))}
D19: {=IF(OR((D18=""),(D18='Calculations'!$K$22)),"",IF((D18)>='Calculations'!$K$22,"",IF((D18+$B$16)>='Calculations'!$K$22,'Calculations'!$K$22,(D18+$B$16))))} | E19: {=IF(OR('Calculations'!$E$26=0,D19>'Calculations'!$K$22),"",IF(SUM('Calculations'!$E$20-'W1 Sheet'!$U$73-D19)>'Calculations'!$E$26,'Calculations'!$E$26,SUM('Calculations'!$E$20-'W1 Sheet'!$U$73-D19)))} | H19: {=IF('Calculations'!$K$10="No data","",ROUNDUP(SUM(('W1 Sheet'!$U$73*('W1 Sheet'!$AC$83-'Calculations'!$K$8))+(K19*('Calculations'!$E$25-'Calculations'!$K$8)))/('Calculations'!$K$8-('Calculations'!$E$22)),0))}
B20: Eq14 | D20: {=IF(OR((D19=""),(D19='Calculations'!$K$22)),"",IF((D19)>='Calculations'!$K$22,"",IF((D19+$B$16)>='Calculations'!$K$22,'Calculations'!$K$22,(D19+$B$16))))} | E20: {=IF(OR('Calculations'!$E$26=0,D20>'Calculations'!$K$22),"",IF(SUM('Calculations'!$E$20-'W1 Sheet'!$U$73-D20)>'Calculations'!$E$26,'Calculations'!$E$26,SUM('Calculations'!$E$20-'W1 Sheet'!$U$73-D20)))} | H20: {=IF('Calculations'!$K$10="No data","",ROUNDUP(SUM(('W1 Sheet'!$U$73*('W1 Sheet'!$AC$83-'Calculations'!$K$8))+(K20*('Calculations'!$E$25-'Calculations'!$K$8)))/('Calculations'!$K$8-('Calculations'!$E$22)),0))}
D21: {=IF(OR((D20=""),(D20='Calculations'!$K$22)),"",IF((D20)>='Calculations'!$K$22,"",IF((D20+$B$16)>='Calculations'!$K$22,'Calculations'!$K$22,(D20+$B$16))))} | E21: {=IF(OR('Calculations'!$E$26=0,D21>'Calculations'!$K$22),"",IF(SUM('Calculations'!$E$20-'W1 Sheet'!$U$73-D21)>'Calculations'!$E$26,'Calculations'!$E$26,SUM('Calculations'!$E$20-'W1 Sheet'!$U$73-D21)))} | H21: {=IF('Calculations'!$K$10="No data","",ROUNDUP(SUM(('W1 Sheet'!$U$73*('W1 Sheet'!$AC$83-'Calculations'!$K$8))+(K21*('Calculations'!$E$25-'Calculations'!$K$8)))/('Calculations'!$K$8-('Calculations'!$E$22)),0))}
D22: {=IF(OR((D21=""),(D21='Calculations'!$K$22)),"",IF((D21)>='Calculations'!$K$22,"",IF((D21+$B$16)>='Calculations'!$K$22,'Calculations'!$K$22,(D21+$B$16))))} | E22: {=IF(OR('Calculations'!$E$26=0,D22>'Calculations'!$K$22),"",IF(SUM('Calculations'!$E$20-'W1 Sheet'!$U$73-D22)>'Calculations'!$E$26,'Calculations'!$E$26,SUM('Calculations'!$E$20-'W1 Sheet'!$U$73-D22)))}
D23: {=IF(OR((D22=""),(D22='Calculations'!$K$22)),"",IF((D22)>='Calculations'!$K$22,"",IF((D22+$B$16)>='Calculations'!$K$22,'Calculations'!$K$22,(D22+$B$16))))} | E23: {=IF(OR('Calculations'!$E$26=0,D23>'Calculations'!$K$22),"",IF(SUM('Calculations'!$E$20-'W1 Sheet'!$U$73-D23)>'Calculations'!$E$26,'Calculations'!$E$26,SUM('Calculations'!$E$20-'W1 Sheet'!$U$73-D23)))}
D24: {=IF(OR((D23=""),(D23='Calculations'!$K$22)),"",IF((D23)>='Calculations'!$K$22,"",IF((D23+$B$16)>='Calculations'!$K$22,'Calculations'!$K$22,(D23+$B$16))))} | E24: {=IF(OR('Calculations'!$E$26=0,D24>'Calculations'!$K$22),"",IF(SUM('Calculations'!$E$20-'W1 Sheet'!$U$73-D24)>'Calculations'!$E$26,'Calculations'!$E$26,SUM('Calculations'!$E$20-'W1 Sheet'!$U$73-D24)))}
D30: Seat limit 110Kg | H30: Max fuselage load | J30: {='Calculations'!$K$16} -> 244.5 | K30: Kg
C31: P1 | D31: Min P2 | E31: Max P2 | F31: Max P2 | G31: Max P2 | H31: Max | I31: Front Pilot | J31: Min P2 for aft | K31: Max P2 for
C32: Kg | D32: Aft CG | E32: Fwd CG | F32: Dry limit | G32: Wet limit | H32: MWNLP | I32: Kg | J32: CG limit (Kg) | K32: ALL limits (Kg)
C33: 20 | D33: {=IF('Calculations'!$E$23=0,0,((('W1 Sheet'!$U$73*'W1 Sheet'!$AC$83)+(('Calculations'!$E$22*(C33)))-('Calculations'!$K$8*'W1 Sheet'!$U$73)-('Calculations'!$K$8*(C33)))/('Calculations'!$K$8-'Calculations'!$E$23)))} | E33: {=IF('Calculations'!$E$23=0,0,SUM(((('W1 Sheet'!$U$73*'W1 Sheet'!$AC$83)+('Calculations'!$E$22*(C33))-('Calculations'!$E$18*'W1 Sheet'!$U$73)-('Calculations'!$E$18*(C33)))/('Calculations'!$E$18-'Calculations'!$E$23))))} | F33: {=ROUNDDOWN('Calculations'!$E$21-'W1 Sheet'!$U$73-C33,0)} -> 224 | G33: {=ROUNDDOWN('Calculations'!$E$20-'W1 Sheet'!$U$73-C33,0)} -> 318 | H33: {=IF(OR('Calculations'!$E$23=0,'Calculations'!$E$24=0),0,('Calculations'!$E$24-'W1 Sheet'!$U$78-C33))} -> 224 | I33: 20 | J33: {=IF('Calculations'!$E$23=0,0,IF(OR(D33>110,(D33+C33)>$J$30),"",IF(D33<0,0,ROUNDUP(D33,0))))} | K33: {=ROUNDDOWN(MIN(E33,F33,G33,H33,'Calculations'!$K$22),0)}
C34: 25 | D34: {=IF('Calculations'!$E$23=0,0,((('W1 Sheet'!$U$73*'W1 Sheet'!$AC$83)+(('Calculations'!$E$22*(C34)))-('Calculations'!$K$8*'W1 Sheet'!$U$73)-('Calculations'!$K$8*(C34)))/('Calculations'!$K$8-'Calculations'!$E$23)))} | E34: {=IF('Calculations'!$E$23=0,0,SUM(((('W1 Sheet'!$U$73*'W1 Sheet'!$AC$83)+('Calculations'!$E$22*(C34))-('Calculations'!$E$18*'W1 Sheet'!$U$73)-('Calculations'!$E$18*(C34)))/('Calculations'!$E$18-'Calculations'!$E$23))))} | F34: {=ROUNDDOWN('Calculations'!$E$21-'W1 Sheet'!$U$73-C34,0)} -> 219 | G34: {=ROUNDDOWN('Calculations'!$E$20-'W1 Sheet'!$U$73-C34,0)} -> 313 | H34: {=IF(OR('Calculations'!$E$23=0,'Calculations'!$E$24=0),0,('Calculations'!$E$24-'W1 Sheet'!$U$78-C34))} -> 219 | I34: 25 | J34: {=IF('Calculations'!$E$23=0,0,IF(OR(D34>110,(D34+C34)>$J$30),"",IF(D34<0,0,ROUNDUP(D34,0))))} | K34: {=ROUNDDOWN(MIN(E34,F34,G34,H34,'Calculations'!$K$22),0)}
C35: 30 | D35: {=IF('Calculations'!$E$23=0,0,((('W1 Sheet'!$U$73*'W1 Sheet'!$AC$83)+(('Calculations'!$E$22*(C35)))-('Calculations'!$K$8*'W1 Sheet'!$U$73)-('Calculations'!$K$8*(C35)))/('Calculations'!$K$8-'Calculations'!$E$23)))} | E35: {=IF('Calculations'!$E$23=0,0,SUM(((('W1 Sheet'!$U$73*'W1 Sheet'!$AC$83)+('Calculations'!$E$22*(C35))-('Calculations'!$E$18*'W1 Sheet'!$U$73)-('Calculations'!$E$18*(C35)))/('Calculations'!$E$18-'Calculations'!$E$23))))} | F35: {=ROUNDDOWN('Calculations'!$E$21-'W1 Sheet'!$U$73-C35,0)} -> 214 | G35: {=ROUNDDOWN('Calculations'!$E$20-'W1 Sheet'!$U$73-C35,0)} -> 308 | H35: {=IF(OR('Calculations'!$E$23=0,'Calculations'!$E$24=0),0,('Calculations'!$E$24-'W1 Sheet'!$U$78-C35))} -> 214 | I35: 30 | J35: {=IF('Calculations'!$E$23=0,0,IF(OR(D35>110,(D35+C35)>$J$30),"",IF(D35<0,0,ROUNDUP(D35,0))))} | K35: {=ROUNDDOWN(MIN(E35,F35,G35,H35,'Calculations'!$K$22),0)}
C36: 35 | D36: {=IF('Calculations'!$E$23=0,0,((('W1 Sheet'!$U$73*'W1 Sheet'!$AC$83)+(('Calculations'!$E$22*(C36)))-('Calculations'!$K$8*'W1 Sheet'!$U$73)-('Calculations'!$K$8*(C36)))/('Calculations'!$K$8-'Calculations'!$E$23)))} | E36: {=IF('Calculations'!$E$23=0,0,SUM(((('W1 Sheet'!$U$73*'W1 Sheet'!$AC$83)+('Calculations'!$E$22*(C36))-('Calculations'!$E$18*'W1 Sheet'!$U$73)-('Calculations'!$E$18*(C36)))/('Calculations'!$E$18-'Calculations'!$E$23))))} | F36: {=ROUNDDOWN('Calculations'!$E$21-'W1 Sheet'!$U$73-C36,0)} -> 209 | G36: {=ROUNDDOWN('Calculations'!$E$20-'W1 Sheet'!$U$73-C36,0)} -> 303 | H36: {=IF(OR('Calculations'!$E$23=0,'Calculations'!$E$24=0),0,('Calculations'!$E$24-'W1 Sheet'!$U$78-C36))} -> 209 | I36: 35 | J36: {=IF('Calculations'!$E$23=0,0,IF(OR(D36>110,(D36+C36)>$J$30),"",IF(D36<0,0,ROUNDUP(D36,0))))} | K36: {=ROUNDDOWN(MIN(E36,F36,G36,H36,'Calculations'!$K$22),0)}
C37: 40 | D37: {=IF('Calculations'!$E$23=0,0,((('W1 Sheet'!$U$73*'W1 Sheet'!$AC$83)+(('Calculations'!$E$22*(C37)))-('Calculations'!$K$8*'W1 Sheet'!$U$73)-('Calculations'!$K$8*(C37)))/('Calculations'!$K$8-'Calculations'!$E$23)))} | E37: {=IF('Calculations'!$E$23=0,0,SUM(((('W1 Sheet'!$U$73*'W1 Sheet'!$AC$83)+('Calculations'!$E$22*(C37))-('Calculations'!$E$18*'W1 Sheet'!$U$73)-('Calculations'!$E$18*(C37)))/('Calculations'!$E$18-'Calculations'!$E$23))))} | F37: {=ROUNDDOWN('Calculations'!$E$21-'W1 Sheet'!$U$73-C37,0)} -> 204 | G37: {=ROUNDDOWN('Calculations'!$E$20-'W1 Sheet'!$U$73-C37,0)} -> 298 | H37: {=IF(OR('Calculations'!$E$23=0,'Calculations'!$E$24=0),0,('Calculations'!$E$24-'W1 Sheet'!$U$78-C37))} -> 204 | I37: 40 | J37: {=IF('Calculations'!$E$23=0,0,IF(OR(D37>110,(D37+C37)>$J$30),"",IF(D37<0,0,ROUNDUP(D37,0))))} | K37: {=ROUNDDOWN(MIN(E37,F37,G37,H37,'Calculations'!$K$22),0)}
C38: {=SUM(C37+5)} -> 45 | D38: {=IF('Calculations'!$E$23=0,0,((('W1 Sheet'!$U$73*'W1 Sheet'!$AC$83)+(('Calculations'!$E$22*(C38)))-('Calculations'!$K$8*'W1 Sheet'!$U$73)-('Calculations'!$K$8*(C38)))/('Calculations'!$K$8-'Calculations'!$E$23)))} | E38: {=IF('Calculations'!$E$23=0,0,SUM(((('W1 Sheet'!$U$73*'W1 Sheet'!$AC$83)+('Calculations'!$E$22*(C38))-('Calculations'!$E$18*'W1 Sheet'!$U$73)-('Calculations'!$E$18*(C38)))/('Calculations'!$E$18-'Calculations'!$E$23))))} | F38: {=ROUNDDOWN('Calculations'!$E$21-'W1 Sheet'!$U$73-C38,0)} -> 199 | G38: {=ROUNDDOWN('Calculations'!$E$20-'W1 Sheet'!$U$73-C38,0)} -> 293 | H38: {=IF(OR('Calculations'!$E$23=0,'Calculations'!$E$24=0),0,('Calculations'!$E$24-'W1 Sheet'!$U$78-C38))} -> 199 | I38: {=SUM(I37+5)} -> 45 | J38: {=IF('Calculations'!$E$23=0,0,IF(OR(D38>110,(D38+C38)>$J$30),"",IF(D38<0,0,ROUNDUP(D38,0))))} | K38: {=ROUNDDOWN(MIN(E38,F38,G38,H38,'Calculations'!$K$22),0)}
C39: {=SUM(C38+5)} -> 50 | D39: {=IF('Calculations'!$E$23=0,0,((('W1 Sheet'!$U$73*'W1 Sheet'!$AC$83)+(('Calculations'!$E$22*(C39)))-('Calculations'!$K$8*'W1 Sheet'!$U$73)-('Calculations'!$K$8*(C39)))/('Calculations'!$K$8-'Calculations'!$E$23)))} | E39: {=IF('Calculations'!$E$23=0,0,SUM(((('W1 Sheet'!$U$73*'W1 Sheet'!$AC$83)+('Calculations'!$E$22*(C39))-('Calculations'!$E$18*'W1 Sheet'!$U$73)-('Calculations'!$E$18*(C39)))/('Calculations'!$E$18-'Calculations'!$E$23))))} | F39: {=ROUNDDOWN('Calculations'!$E$21-'W1 Sheet'!$U$73-C39,0)} -> 194 | G39: {=ROUNDDOWN('Calculations'!$E$20-'W1 Sheet'!$U$73-C39,0)} -> 288 | H39: {=IF(OR('Calculations'!$E$23=0,'Calculations'!$E$24=0),0,('Calculations'!$E$24-'W1 Sheet'!$U$78-C39))} -> 194 | I39: {=SUM(I38+5)} -> 50 | J39: {=IF('Calculations'!$E$23=0,0,IF(OR(D39>110,(D39+C39)>$J$30),"",IF(D39<0,0,ROUNDUP(D39,0))))} | K39: {=ROUNDDOWN(MIN(E39,F39,G39,H39,'Calculations'!$K$22),0)}
C40: {=SUM(C39+5)} -> 55 | D40: {=IF('Calculations'!$E$23=0,0,((('W1 Sheet'!$U$73*'W1 Sheet'!$AC$83)+(('Calculations'!$E$22*(C40)))-('Calculations'!$K$8*'W1 Sheet'!$U$73)-('Calculations'!$K$8*(C40)))/('Calculations'!$K$8-'Calculations'!$E$23)))} | E40: {=IF('Calculations'!$E$23=0,0,SUM(((('W1 Sheet'!$U$73*'W1 Sheet'!$AC$83)+('Calculations'!$E$22*(C40))-('Calculations'!$E$18*'W1 Sheet'!$U$73)-('Calculations'!$E$18*(C40)))/('Calculations'!$E$18-'Calculations'!$E$23))))} | F40: {=ROUNDDOWN('Calculations'!$E$21-'W1 Sheet'!$U$73-C40,0)} -> 189 | G40: {=ROUNDDOWN('Calculations'!$E$20-'W1 Sheet'!$U$73-C40,0)} -> 283 | H40: {=IF(OR('Calculations'!$E$23=0,'Calculations'!$E$24=0),0,('Calculations'!$E$24-'W1 Sheet'!$U$78-C40))} -> 189 | I40: {=SUM(I39+5)} -> 55 | J40: {=IF('Calculations'!$E$23=0,0,IF(OR(D40>110,(D40+C40)>$J$30),"",IF(D40<0,0,ROUNDUP(D40,0))))} | K40: {=ROUNDDOWN(MIN(E40,F40,G40,H40,'Calculations'!$K$22),0)}
C41: {=SUM(C40+5)} -> 60 | D41: {=IF('Calculations'!$E$23=0,0,((('W1 Sheet'!$U$73*'W1 Sheet'!$AC$83)+(('Calculations'!$E$22*(C41)))-('Calculations'!$K$8*'W1 Sheet'!$U$73)-('Calculations'!$K$8*(C41)))/('Calculations'!$K$8-'Calculations'!$E$23)))} | E41: {=IF('Calculations'!$E$23=0,0,SUM(((('W1 Sheet'!$U$73*'W1 Sheet'!$AC$83)+('Calculations'!$E$22*(C41))-('Calculations'!$E$18*'W1 Sheet'!$U$73)-('Calculations'!$E$18*(C41)))/('Calculations'!$E$18-'Calculations'!$E$23))))} | F41: {=ROUNDDOWN('Calculations'!$E$21-'W1 Sheet'!$U$73-C41,0)} -> 184 | G41: {=ROUNDDOWN('Calculations'!$E$20-'W1 Sheet'!$U$73-C41,0)} -> 278 | H41: {=IF(OR('Calculations'!$E$23=0,'Calculations'!$E$24=0),0,('Calculations'!$E$24-'W1 Sheet'!$U$78-C41))} -> 184 | I41: {=SUM(I40+5)} -> 60 | J41: {=IF('Calculations'!$E$23=0,0,IF(OR(D41>110,(D41+C41)>$J$30),"",IF(D41<0,0,ROUNDUP(D41,0))))} | K41: {=ROUNDDOWN(MIN(E41,F41,G41,H41,'Calculations'!$K$22),0)}
C42: {=SUM(C41+5)} -> 65 | D42: {=IF('Calculations'!$E$23=0,0,((('W1 Sheet'!$U$73*'W1 Sheet'!$AC$83)+(('Calculations'!$E$22*(C42)))-('Calculations'!$K$8*'W1 Sheet'!$U$73)-('Calculations'!$K$8*(C42)))/('Calculations'!$K$8-'Calculations'!$E$23)))} | E42: {=IF('Calculations'!$E$23=0,0,SUM(((('W1 Sheet'!$U$73*'W1 Sheet'!$AC$83)+('Calculations'!$E$22*(C42))-('Calculations'!$E$18*'W1 Sheet'!$U$73)-('Calculations'!$E$18*(C42)))/('Calculations'!$E$18-'Calculations'!$E$23))))} | F42: {=ROUNDDOWN('Calculations'!$E$21-'W1 Sheet'!$U$73-C42,0)} -> 179 | G42: {=ROUNDDOWN('Calculations'!$E$20-'W1 Sheet'!$U$73-C42,0)} -> 273 | H42: {=IF(OR('Calculations'!$E$23=0,'Calculations'!$E$24=0),0,('Calculations'!$E$24-'W1 Sheet'!$U$78-C42))} -> 179 | I42: {=SUM(I41+5)} -> 65 | J42: {=IF('Calculations'!$E$23=0,0,IF(OR(D42>110,(D42+C42)>$J$30),"",IF(D42<0,0,ROUNDUP(D42,0))))} | K42: {=ROUNDDOWN(MIN(E42,F42,G42,H42,'Calculations'!$K$22),0)}
C43: {=SUM(C42+5)} -> 70 | D43: {=IF('Calculations'!$E$23=0,0,((('W1 Sheet'!$U$73*'W1 Sheet'!$AC$83)+(('Calculations'!$E$22*(C43)))-('Calculations'!$K$8*'W1 Sheet'!$U$73)-('Calculations'!$K$8*(C43)))/('Calculations'!$K$8-'Calculations'!$E$23)))} | E43: {=IF('Calculations'!$E$23=0,0,SUM(((('W1 Sheet'!$U$73*'W1 Sheet'!$AC$83)+('Calculations'!$E$22*(C43))-('Calculations'!$E$18*'W1 Sheet'!$U$73)-('Calculations'!$E$18*(C43)))/('Calculations'!$E$18-'Calculations'!$E$23))))} | F43: {=ROUNDDOWN('Calculations'!$E$21-'W1 Sheet'!$U$73-C43,0)} -> 174 | G43: {=ROUNDDOWN('Calculations'!$E$20-'W1 Sheet'!$U$73-C43,0)} -> 268 | H43: {=IF(OR('Calculations'!$E$23=0,'Calculations'!$E$24=0),0,('Calculations'!$E$24-'W1 Sheet'!$U$78-C43))} -> 174 | I43: {=SUM(I42+5)} -> 70 | J43: {=IF('Calculations'!$E$23=0,0,IF(OR(D43>110,(D43+C43)>$J$30),"",IF(D43<0,0,ROUNDUP(D43,0))))} | K43: {=ROUNDDOWN(MIN(E43,F43,G43,H43,'Calculations'!$K$22),0)}
C44: {=SUM(C43+5)} -> 75 | D44: {=IF('Calculations'!$E$23=0,0,((('W1 Sheet'!$U$73*'W1 Sheet'!$AC$83)+(('Calculations'!$E$22*(C44)))-('Calculations'!$K$8*'W1 Sheet'!$U$73)-('Calculations'!$K$8*(C44)))/('Calculations'!$K$8-'Calculations'!$E$23)))} | E44: {=IF('Calculations'!$E$23=0,0,SUM(((('W1 Sheet'!$U$73*'W1 Sheet'!$AC$83)+('Calculations'!$E$22*(C44))-('Calculations'!$E$18*'W1 Sheet'!$U$73)-('Calculations'!$E$18*(C44)))/('Calculations'!$E$18-'Calculations'!$E$23))))} | F44: {=ROUNDDOWN('Calculations'!$E$21-'W1 Sheet'!$U$73-C44,0)} -> 169 | G44: {=ROUNDDOWN('Calculations'!$E$20-'W1 Sheet'!$U$73-C44,0)} -> 263 | H44: {=IF(OR('Calculations'!$E$23=0,'Calculations'!$E$24=0),0,('Calculations'!$E$24-'W1 Sheet'!$U$78-C44))} -> 169 | I44: {=SUM(I43+5)} -> 75 | J44: {=IF('Calculations'!$E$23=0,0,IF(OR(D44>110,(D44+C44)>$J$30),"",IF(D44<0,0,ROUNDUP(D44,0))))} | K44: {=ROUNDDOWN(MIN(E44,F44,G44,H44,'Calculations'!$K$22),0)}
C45: {=SUM(C44+5)} -> 80 | D45: {=IF('Calculations'!$E$23=0,0,((('W1 Sheet'!$U$73*'W1 Sheet'!$AC$83)+(('Calculations'!$E$22*(C45)))-('Calculations'!$K$8*'W1 Sheet'!$U$73)-('Calculations'!$K$8*(C45)))/('Calculations'!$K$8-'Calculations'!$E$23)))} | E45: {=IF('Calculations'!$E$23=0,0,SUM(((('W1 Sheet'!$U$73*'W1 Sheet'!$AC$83)+('Calculations'!$E$22*(C45))-('Calculations'!$E$18*'W1 Sheet'!$U$73)-('Calculations'!$E$18*(C45)))/('Calculations'!$E$18-'Calculations'!$E$23))))} | F45: {=ROUNDDOWN('Calculations'!$E$21-'W1 Sheet'!$U$73-C45,0)} -> 164 | G45: {=ROUNDDOWN('Calculations'!$E$20-'W1 Sheet'!$U$73-C45,0)} -> 258 | H45: {=IF(OR('Calculations'!$E$23=0,'Calculations'!$E$24=0),0,('Calculations'!$E$24-'W1 Sheet'!$U$78-C45))} -> 164 | I45: {=SUM(I44+5)} -> 80 | J45: {=IF('Calculations'!$E$23=0,0,IF(OR(D45>110,(D45+C45)>$J$30),"",IF(D45<0,0,ROUNDUP(D45,0))))} | K45: {=ROUNDDOWN(MIN(E45,F45,G45,H45,'Calculations'!$K$22),0)}
C46: {=SUM(C45+5)} -> 85 | D46: {=IF('Calculations'!$E$23=0,0,((('W1 Sheet'!$U$73*'W1 Sheet'!$AC$83)+(('Calculations'!$E$22*(C46)))-('Calculations'!$K$8*'W1 Sheet'!$U$73)-('Calculations'!$K$8*(C46)))/('Calculations'!$K$8-'Calculations'!$E$23)))} | E46: {=IF('Calculations'!$E$23=0,0,SUM(((('W1 Sheet'!$U$73*'W1 Sheet'!$AC$83)+('Calculations'!$E$22*(C46))-('Calculations'!$E$18*'W1 Sheet'!$U$73)-('Calculations'!$E$18*(C46)))/('Calculations'!$E$18-'Calculations'!$E$23))))} | F46: {=ROUNDDOWN('Calculations'!$E$21-'W1 Sheet'!$U$73-C46,0)} -> 159 | G46: {=ROUNDDOWN('Calculations'!$E$20-'W1 Sheet'!$U$73-C46,0)} -> 253 | H46: {=IF(OR('Calculations'!$E$23=0,'Calculations'!$E$24=0),0,('Calculations'!$E$24-'W1 Sheet'!$U$78-C46))} -> 159 | I46: {=SUM(I45+5)} -> 85 | J46: {=IF('Calculations'!$E$23=0,0,IF(OR(D46>110,(D46+C46)>$J$30),"",IF(D46<0,0,ROUNDUP(D46,0))))} | K46: {=ROUNDDOWN(MIN(E46,F46,G46,H46,'Calculations'!$K$22),0)}
C47: {=SUM(C46+5)} -> 90 | D47: {=IF('Calculations'!$E$23=0,0,((('W1 Sheet'!$U$73*'W1 Sheet'!$AC$83)+(('Calculations'!$E$22*(C47)))-('Calculations'!$K$8*'W1 Sheet'!$U$73)-('Calculations'!$K$8*(C47)))/('Calculations'!$K$8-'Calculations'!$E$23)))} | E47: {=IF('Calculations'!$E$23=0,0,SUM(((('W1 Sheet'!$U$73*'W1 Sheet'!$AC$83)+('Calculations'!$E$22*(C47))-('Calculations'!$E$18*'W1 Sheet'!$U$73)-('Calculations'!$E$18*(C47)))/('Calculations'!$E$18-'Calculations'!$E$23))))} | F47: {=ROUNDDOWN('Calculations'!$E$21-'W1 Sheet'!$U$73-C47,0)} -> 154 | G47: {=ROUNDDOWN('Calculations'!$E$20-'W1 Sheet'!$U$73-C47,0)} -> 248 | H47: {=IF(OR('Calculations'!$E$23=0,'Calculations'!$E$24=0),0,('Calculations'!$E$24-'W1 Sheet'!$U$78-C47))} -> 154 | I47: {=SUM(I46+5)} -> 90 | J47: {=IF('Calculations'!$E$23=0,0,IF(OR(D47>110,(D47+C47)>$J$30),"",IF(D47<0,0,ROUNDUP(D47,0))))} | K47: {=ROUNDDOWN(MIN(E47,F47,G47,H47,'Calculations'!$K$22),0)}
...

Sheet Aircraft Data
A1: Type | B1: Wet Kg | C1: Dry Kg | D1: Non lift Kg | E1: CG fwd mm | F1: CG aft mm | G1: Pilot P1 arm mm | H1: Ballast arm mm | I1: Water Ltrs | J1: Smooth air Kts | K1: Rough air Kts | L1: Maneuv sp Kts | M1: Aerotow Kts | N1: Winch Kts | O1: Weak link Kg | P1: Issue date | Q1: P2 moment | R1: Datum | S1: Level | T1: Model | V1: Fuse fuel Moment | W1: Tail Ballast Moment | X1: Wing fuel moment | Y1: Wing water moment
A2: A blank sheet | T2: 1 | U2: A blank sheet
A3: ASH 25E | B3: 750 | C3: 735 | D3: 425 | E3: 210 | F3: 400 | G3: -1330 | H3: -1849 | I3: 55 | P3: 35187 | Q3: -363 | R3: WRLE | S3: REAR FUSE LEVEL
A4: ASH 25m | B4: 790 | C4: 777 | D4: 460 | E4: 220 | F4: 400 | G4: -1322 | I4: 120 | Q4: -339 | T4: 1 | U4: ASH 25m | V4: 250 | W4: 5400 | X4: 207 | Y4: 207
A5: ASK 21 | B5: 600 | C5: 600 | D5: 410 | E5: 234 | F5: 469 | G5: -1185 | H5: -1640 | J5: 151 | K5: 108 | L5: 97 | M5: 97 | N5: 81 | O5: 600 | P5: 35629 | Q5: -80 | R5: WRLE | S5: 1000:52 top rear fuse | T5: 3 | U5: ASK21 | V5: 900
A6: ASK21Mi | B6: 0 | C6: 705 | D6: 510 | E6: 234 | F6: 469 | G6: -1185 | H6: -1640 | J6: 151 | K6: 97 | L6: 97 | M6: 97 | N6: 81 | O6: 850 | P6: 39590 | Q6: -80 | R6: WRLE | S6: 1000:52 top fuse | T6: 1 | U6: ASK21Mi
A7: Astir CS | B7: 450 | C7: 380 | D7: 240 | E7: 310 | F7: 480 | G7: -475 | H7: -1000 | I7: 100 | T7: 1 | U7: Astir CS
A8: ASW19B | B8: 454 | C8: 375 | D8: 230 | E8: 240 | F8: 384 | G8: -570 | I8: 100 | T8: 1 | U8: ASW19B
A9: Asw20 bl 16mtr | B9: 430 | C9: 411.5 | D9: 245 | E9: 240 | F9: 360 | G9: -550 | H9: -1880 | I9: 100 | J9: 143 | K9: 92 | L9: 92 | M9: 92 | N9: 70 | O9: 600 | P9: 35860 | R9: WRLE | S9: 41.697917
A10: ASW20B | B10: 525 | C10: 525 | D10: 245 | E10: 240 | F10: 360 | G10: -550 | H10: -1880 | I10: 150 | J10: 151 | O10: 540 | P10: 35949 | R10: WRLE | S10: 1000:45 top rear fuse | T10: 1 | U10: ASW20B
A11: Asw20bl 15mtr | B11: 525 | C11: 407.5 | D11: 245 | E11: 240 | F11: 360 | G11: -550 | H11: -1880 | I11: 150 | J11: 143 | K11: 92 | L11: 92 | M11: 92 | N11: 70 | O11: 600 | P11: 35860 | R11: WRLE | S11: 41.697917
A12: Blanik l13 | C12: 500 | E12: 112 | F12: 300 | G12: -1232 | J12: 136 | K12: 78 | L12: 78 | M12: 76 | N12: 65 | O12: 400 | P12: 34828 | Q12: -112 | R12: WRLE | S12: fuse datum level | T12: 1 | U12: Blanik l13
A13: Blanik L13 aero | C13: 400 | E13: 112 | F13: 300 | G13: -1232 | J13: 136 | K13: 78 | L13: 78 | M13: 76 | N13: 65 | P13: 34828 | Q13: -112 | R13: WRLE | T13: 1 | U13: Blanik L13 aero
A14: Cirrus | B14: 390 | C14: 390 | D14: 220 | E14: 250 | F14: 400 | G14: -440 | H14: -1600 | I14: 80 | T14: 1 | U14: Cirrus
A15: DG 400 15mtr | B15: 480 | C15: 480 | D15: 320 | E15: 250 | F15: 390 | G15: -526 | I15: 90 | R15: WRLE | S15: 1000:36.7 top fuse | T15: 1 | U15: DG 400 15mtr
A16: DG 400 17mtr | B16: 460 | C16: 460 | D16: 320 | E16: 250 | F16: 390 | G16: -526 | I16: 90 | R16: WRLE | S16: 1000:36.7 top of fuse | T16: 1 | U16: DG 400 17mtr
A17: DG1000 aero 18 | B17: 630 | C17: 630 | D17: 469 | E17: 190 | F17: 440 | G17: -1335 | H17: -1960 | I17: 160 | Q17: -272 | R17: WRLE | S17: 1000:33 top fuse | U17: Dg 1000 aero 18 | W17: 5400
A18: DG1000 utility 18 | B18: 750 | C18: 656 | D18: 469 | E18: 190 | F18: 440 | G18: -1335 | H18: -1960 | I18: 160 | Q18: -272 | R18: WRLE | S18: 1000:33 top fuse | U18: DG 1000 utility 18 | W18: 5400
A19: DG1000 utility 20 | B19: 750 | C19: 661 | D19: 469 | E19: 190 | F19: 440 | G19: -1335 | H19: -1960 | I19: 160 | Q19: -272 | R19: WRLE | S19: 1000:33 top fuse | U19: DG1000 utility20 | W19: 5400
A20: DG303 | B20: 450 | C20: 376.5 | D20: 240 | E20: 160 | F20: 325 | G20: -549 | H20: -1250 | I20: 130 | T20: 1 | U20: DG303
A21: DG500M-XQA | B21: 825 | C21: 803.4 | D21: 560 | E21: 255 | F21: 480 | G21: -1295 | H21: -2455 | I21: 100 | J21: 146 | K21: 106 | L21: 106 | M21: 106 | N21: 76 | O21: 1000 | P21: 34668 | Q21: -232 | R21: WRLE | S21: 41.689583 | T21: 1 | U21: DG500M | V21: 409
A22: Duo Discus M | B22: 700 | C22: 700 | D22: 490 | E22: 45 | F22: 250 | G22: -1400 | H22: -1855 | J22: 135 | K22: 97 | L22: 97 | M22: 97 | N22: 81 | O22: 910 | P22: 37624 | Q22: -290 | R22: WRLE | S22: 1000:45 top fuse | T22: 1 | U22: DUO Discus M
A23: G103 Acro 600kg | C23: 600 | D23: 400 | E23: 260 | F23: 460 | G23: -1150 | H23: -1450 | Q23: 40 | U23: G103 Twin Acro
A24: Grob 109A | B24: 0 | C24: 825 | D24: 640 | E24: 380 | F24: 465 | G24: 90 | H24: -300 | I24: 0 | J24: 130 | K24: 100 | L24: 100 | P24: 35592 | Q24: 90 | R24: WRLE | S24: level 500 in front of fin | T24: 1 | U24: Grob 109 | V24: 1035
A25: Grob103 twin500kg | C25: 580 | D25: 400 | E25: 260 | F25: 460 | G25: -1150 | H25: -1450 | J25: 135 | K25: 92 | L25: 92 | M25: 92 | N25: 65 | O25: 600 | P25: 38825 | Q25: 40 | R25: WRLE | S25: 1000:40 | T25: 1 | U25: Grob103 twin
A26: Hornet | B26: 420 | C26: 420 | D26: 225 | E26: 250 | F26: 375 | G26: -410 | I26: 100 | J26: 135 | K26: 81 | L26: 81 | M26: 73 | N26: 81 | O26: 500 | P26: 34166 | R26: WRLE | S26: 4.2027778 | T26: 1 | U26: Hornet
A27: IS28 B2 | B27: 590 | C27: 590 | E27: 249 | F27: 531 | G27: -1361 | H27: -1835 | J27: 124 | K27: 89 | L27: 89 | M27: 75 | N27: 67 | O27: 770 | P27: 37776 | Q27: -254 | R27: WRLE | S27: See data sheet | T27: 1 | U27: IS28 B2
A28: IS28 B2 Aero | B28: 520 | C28: 520 | E28: 249 | F28: 531 | G28: -1361 | H28: -1835 | I28: 0 | J28: 124 | K28: 89 | L28: 89 | M28: 75 | N28: 67 | O28: 680 | P28: 37776 | Q28: -254 | R28: WRLE | S28: 2.35 deg on tail boom | T28: 1 | U28: IS28 B2 Aero
A29: Jantar Junior | B29: 380 | C29: 380 | D29: 275 | E29: 287 | F29: 482 | G29: -500 | H29: -970 | Q29: na | R29: WRLE | S29: wings level
A30: Jantar std2 | B30: 535 | C30: 385 | D30: 245 | E30: 148 | F30: 336 | G30: -616 | I30: 150 | J30: 154 | K30: 108 | L30: 92 | M30: 81 | N30: 67 | O30: 690 | P30: 35676 | R30: WRLE | S30: T/E 22mm below L/E | T30: 1 | U30: Jantar std2
A31: Jantar Std3 | B31: 540 | C31: 390 | D31: 243 | E31: 148 | F31: 336 | G31: -605 | I31: 150 | J31: 154 | K31: 108 | L31: 92 | M31: 81 | N31: 67 | O31: 690 | P31: 41155 | R31: WRLE | S31: T/E 22mm below L/E | T31: 1 | U31: Jantar sStd3
A32: LS1f | B32: 390 | C32: 390 | D32: 230 | E32: 220 | F32: 420 | G32: -600 | I32: 90 | J32: 135 | K32: 135 | L32: 92 | M32: 92 | N32: 70 | O32: 500 | P32: 35012 | R32: WRLE | S32: underside fuse level | T32: 1 | U32: LS1f
A33: LS4 | B33: 472 | C33: 472 | D33: 230 | E33: 225 | F33: 375 | G33: -527 | I33: 140 | J33: 146 | K33: 97 | L33: 97 | M33: 97 | N33: 70 | O33: 600 | P33: 35599 | R33: WRLE | S33: bott rear fuse horizontal | T33: 1 | U33: LS4
A34: LS4A | B34: 525 | C34: 525 | D34: 230 | E34: 225 | F34: 400 | G34: -527 | I34: 170 | J34: 151 | K34: 103 | L34: 103 | M34: 103 | N34: 76 | O34: 600 | P34: 35599 | R34: WRLE | S34: Bottom fuse horizontal | T34: 1 | U34: LS4A
A35: LS6 | B35: 525 | C35: 380 | D35: 237 | E35: 250 | F35: 400 | G35: -500 | H35: -1650 | I35: 140 | R35: WRLE | S35: Bottom of fuse level
A36: LS8-18 | B36: 525 | C36: 412 | D36: 239 | E36: 280 | F36: 400 | G36: -500 | H36: -1400 | I36: 190 | J36: 151 | K36: 103 | L36: 103 | M36: 103 | N36: 76 | O36: 660 | P36: 32961 | R36: WRLE | S36: Bottom of fuse horizontal | T36: 1 | U36: LS8-18
A37: Mossy | B37: 450 | C37: 380 | D37: 240 | E37: 235 | F37: 360 | G37: -444 | H37: -1570 | R37: wrle
A38: Nimbus 3 DM | B38: 820 | C38: 820 | D38: 515 | E38: 70 | F38: 230 | G38: -1468 | H38: -1960 | I38: 110 | Q38: -339 | R38: WRLE | S38: 1000:45 rear fuse | T38: 1 | U38: Nimbus 3 DM
A39: Nimbus 3T 22m | B39: 750 | C39: 750 | D39: 300 | E39: 270 | F39: 400 | G39: -596 | H39: -1800 | I39: 338 | J39: 146 | K39: 102 | L39: 102 | M39: 97 | N39: 81 | O39: 910 | P39: 34971 | R39: WRLE | S39: 1000::45 | T39: 1 | U39: Nimbus 3T 24.5m
A40: Nimbus 3T 24m | B40: 750 | C40: 750 | D40: 300 | E40: 270 | F40: 400 | G40: -596 | H40: -1800 | I40: 338 | J40: 146 | K40: 102 | L40: 102 | M40: 97 | N40: 81 | O40: 910 | P40: 29/9/1995 | R40: WRLE | S40: 1000::45 top rear fuse | T40: 1 | U40: Nimbus 3T 24m
...
